<?xml version="1.0" ?>
<robot name="RL_manipulator">
	<link name="base_link">
		<visual>
			<geometry>
				<box size="1 1 2"/>
			</geometry>
			<origin rpy="0 0 0" xyz="0 0 1"/>
		</visual>
		<collision>
			<geometry>
				<box size="1 1 2"/>
			</geometry>
		</collision>
		<inertial>
			<mass value="1"/>
			<inertia ixx="0.1" ixy="0.0" ixz="0.0" iyy="0.1" iyz="0.0" izz="0.1"/>
		</inertial>
	</link>
	<link name="slide_track">
		<visual>
			<geometry>
				<box size="1 1 0.5"/>
			</geometry>
			<origin rpy="0 0 0" xyz="0 0 0"/>
		</visual>
		<collision>
			<geometry>
				<box size="1 1 0.5"/>
			</geometry>
		</collision>
		<inertial>
			<mass value="1"/>
			<inertia ixx="0.1" ixy="0.0" ixz="0.0" iyy="0.1" iyz="0.0" izz="0.1"/>
		</inertial>
	</link>
	<joint name="base_link__slide_track" type="fixed">
		<origin rpy="0 0 0" xyz="0 0 2"/>
		<parent link="base_link"/>
		<child link="slide_track"/>
	</joint>
	<link name="mover">
		<visual>
			<geometry>
				<box size="1 1 1"/>
			</geometry>
			<origin rpy="0 0 0" xyz="0 0 0"/>
		</visual>
		<collision>
			<geometry>
				<box size="1 1 1"/>
			</geometry>
		</collision>
		<inertial>
			<mass value="1"/>
			<inertia ixx="0.1" ixy="0.0" ixz="0.0" iyy="0.1" iyz="0.0" izz="0.1"/>
		</inertial>
	</link>
	<joint name="slide_track__mover" type="prismatic">
		<limit effort="1000.0" lower="-0" upper="4" velocity="0.5"/>
		<axis xyz="1 0 0"/>
		<origin rpy="0 0 0" xyz="0 0 0.5"/>
		<parent link="slide_track"/>
		<child link="mover"/>
	</joint>
	<link name="1_arm_virtual">
		<origin xyz="0 0 0"/>
		<inertial>
			<mass value="1"/>
			<inertia ixx="0.1" ixy="0.0" ixz="0.0" iyy="0.1" iyz="0.0" izz="0.1"/>
		</inertial>
	</link>
	<joint name="mover__1_arm_v" type="revolute">
		<limit effort="1000.0" lower="-0.5" upper="0.5" velocity="0"/>
		<axis xyz="0 1 0"/>
		<origin rpy="0 0 0" xyz="0.75 0 0.125"/>
		<parent link="mover"/>
		<child link="1_arm_virtual"/>
	</joint>
	<link name="1_arm_real">
		<visual>
			<geometry>
				<cylinder length="0.5" radius="0.25"/>
			</geometry>
			<origin rpy="0 1.571 0" xyz="0 0 0"/>
		</visual>
		<collision>
			<geometry>
				<cylinder length="0.5" radius="0.25"/>
			</geometry>
		</collision>
		<inertial>
			<mass value="1"/>
			<inertia ixx="0.1" ixy="0.0" ixz="0.0" iyy="0.1" iyz="0.0" izz="0.1"/>
		</inertial>
	</link>
	<joint name="1_arm_v__1_arm_r" type="revolute">
		<limit effort="1000.0" lower="-0.5" upper="0.5" velocity="0"/>
		<axis xyz="0 0 1"/>
		<origin rpy="0 0 0" xyz="0 0 0"/>
		<parent link="1_arm_virtual"/>
		<child link="1_arm_real"/>
	</joint>
	<link name="2_arm_virtual">
		<origin xyz="0 0 0"/>
		<inertial>
			<mass value="1"/>
			<inertia ixx="0.1" ixy="0.0" ixz="0.0" iyy="0.1" iyz="0.0" izz="0.1"/>
		</inertial>
	</link>
	<joint name="1_arm_r__2_arm_v" type="revolute">
		<limit effort="1000.0" lower="-0.5" upper="0.5" velocity="0"/>
		<axis xyz="0 1 0"/>
		<origin rpy="0 0 0" xyz="0.5 0 0"/>
		<parent link="1_arm_real"/>
		<child link="2_arm_virtual"/>
	</joint>
	<link name="2_arm_real">
		<visual>
			<geometry>
				<cylinder length="0.5" radius="0.25"/>
			</geometry>
			<origin rpy="0 1.571 0" xyz="0 0 0"/>
		</visual>
		<collision>
			<geometry>
				<cylinder length="0.5" radius="0.25"/>
			</geometry>
		</collision>
		<inertial>
			<mass value="1"/>
			<inertia ixx="0.1" ixy="0.0" ixz="0.0" iyy="0.1" iyz="0.0" izz="0.1"/>
		</inertial>
	</link>
	<joint name="2_arm_v__2_arm_r" type="revolute">
		<limit effort="1000.0" lower="-0.5" upper="0.5" velocity="0"/>
		<axis xyz="0 0 1"/>
		<origin rpy="0 0 0" xyz="0 0 0"/>
		<parent link="2_arm_virtual"/>
		<child link="2_arm_real"/>
	</joint>
	<link name="3_arm_virtual">
		<origin xyz="0 0 0"/>
		<inertial>
			<mass value="1"/>
			<inertia ixx="0.1" ixy="0.0" ixz="0.0" iyy="0.1" iyz="0.0" izz="0.1"/>
		</inertial>
	</link>
	<joint name="2_arm_r__3_arm_v" type="revolute">
		<limit effort="1000.0" lower="-0.5" upper="0.5" velocity="0"/>
		<axis xyz="0 1 0"/>
		<origin rpy="0 0 0" xyz="0.5 0 0"/>
		<parent link="2_arm_real"/>
		<child link="3_arm_virtual"/>
	</joint>
	<link name="3_arm_real">
		<visual>
			<geometry>
				<cylinder length="0.5" radius="0.25"/>
			</geometry>
			<origin rpy="0 1.571 0" xyz="0 0 0"/>
		</visual>
		<collision>
			<geometry>
				<cylinder length="0.5" radius="0.25"/>
			</geometry>
		</collision>
		<inertial>
			<mass value="1"/>
			<inertia ixx="0.1" ixy="0.0" ixz="0.0" iyy="0.1" iyz="0.0" izz="0.1"/>
		</inertial>
	</link>
	<joint name="3_arm_v__3_arm_r" type="revolute">
		<limit effort="1000.0" lower="-0.5" upper="0.5" velocity="0"/>
		<axis xyz="0 0 1"/>
		<origin rpy="0 0 0" xyz="0 0 0"/>
		<parent link="3_arm_virtual"/>
		<child link="3_arm_real"/>
	</joint>
	<link name="4_arm_virtual">
		<origin xyz="0 0 0"/>
		<inertial>
			<mass value="1"/>
			<inertia ixx="0.1" ixy="0.0" ixz="0.0" iyy="0.1" iyz="0.0" izz="0.1"/>
		</inertial>
	</link>
	<joint name="3_arm_r__4_arm_v" type="revolute">
		<limit effort="1000.0" lower="-0.5" upper="0.5" velocity="0"/>
		<axis xyz="0 1 0"/>
		<origin rpy="0 0 0" xyz="0.5 0 0"/>
		<parent link="3_arm_real"/>
		<child link="4_arm_virtual"/>
	</joint>
	<link name="4_arm_real">
		<visual>
			<geometry>
				<cylinder length="0.5" radius="0.25"/>
			</geometry>
			<origin rpy="0 1.571 0" xyz="0 0 0"/>
		</visual>
		<collision>
			<geometry>
				<cylinder length="0.5" radius="0.25"/>
			</geometry>
		</collision>
		<inertial>
			<mass value="1"/>
			<inertia ixx="0.1" ixy="0.0" ixz="0.0" iyy="0.1" iyz="0.0" izz="0.1"/>
		</inertial>
	</link>
	<joint name="4_arm_v__4_arm_r" type="revolute">
		<limit effort="1000.0" lower="-0.5" upper="0.5" velocity="0"/>
		<axis xyz="0 0 1"/>
		<origin rpy="0 0 0" xyz="0 0 0"/>
		<parent link="4_arm_virtual"/>
		<child link="4_arm_real"/>
	</joint>
	<link name="5_arm_virtual">
		<origin xyz="0 0 0"/>
		<inertial>
			<mass value="1"/>
			<inertia ixx="0.1" ixy="0.0" ixz="0.0" iyy="0.1" iyz="0.0" izz="0.1"/>
		</inertial>
	</link>
	<joint name="4_arm_r__5_arm_v" type="revolute">
		<limit effort="1000.0" lower="-0.5" upper="0.5" velocity="0"/>
		<axis xyz="0 1 0"/>
		<origin rpy="0 0 0" xyz="0.5 0 0"/>
		<parent link="4_arm_real"/>
		<child link="5_arm_virtual"/>
	</joint>
	<link name="5_arm_real">
		<visual>
			<geometry>
				<cylinder length="0.5" radius="0.25"/>
			</geometry>
			<origin rpy="0 1.571 0" xyz="0 0 0"/>
		</visual>
		<collision>
			<geometry>
				<cylinder length="0.5" radius="0.25"/>
			</geometry>
		</collision>
		<inertial>
			<mass value="1"/>
			<inertia ixx="0.1" ixy="0.0" ixz="0.0" iyy="0.1" iyz="0.0" izz="0.1"/>
		</inertial>
	</link>
	<joint name="5_arm_v__5_arm_r" type="revolute">
		<limit effort="1000.0" lower="-0.5" upper="0.5" velocity="0"/>
		<axis xyz="0 0 1"/>
		<origin rpy="0 0 0" xyz="0 0 0"/>
		<parent link="5_arm_virtual"/>
		<child link="5_arm_real"/>
	</joint>
	<link name="6_arm_virtual">
		<origin xyz="0 0 0"/>
		<inertial>
			<mass value="1"/>
			<inertia ixx="0.1" ixy="0.0" ixz="0.0" iyy="0.1" iyz="0.0" izz="0.1"/>
		</inertial>
	</link>
	<joint name="5_arm_r__6_arm_v" type="revolute">
		<limit effort="1000.0" lower="-0.5" upper="0.5" velocity="0"/>
		<axis xyz="0 1 0"/>
		<origin rpy="0 0 0" xyz="0.5 0 0"/>
		<parent link="5_arm_real"/>
		<child link="6_arm_virtual"/>
	</joint>
	<link name="6_arm_real">
		<visual>
			<geometry>
				<cylinder length="0.5" radius="0.25"/>
			</geometry>
			<origin rpy="0 1.571 0" xyz="0 0 0"/>
		</visual>
		<collision>
			<geometry>
				<cylinder length="0.5" radius="0.25"/>
			</geometry>
		</collision>
		<inertial>
			<mass value="1"/>
			<inertia ixx="0.1" ixy="0.0" ixz="0.0" iyy="0.1" iyz="0.0" izz="0.1"/>
		</inertial>
	</link>
	<joint name="6_arm_v__6_arm_r" type="revolute">
		<limit effort="1000.0" lower="-0.5" upper="0.5" velocity="0"/>
		<axis xyz="0 0 1"/>
		<origin rpy="0 0 0" xyz="0 0 0"/>
		<parent link="6_arm_virtual"/>
		<child link="6_arm_real"/>
	</joint>
	<link name="7_arm_virtual">
		<origin xyz="0 0 0"/>
		<inertial>
			<mass value="1"/>
			<inertia ixx="0.1" ixy="0.0" ixz="0.0" iyy="0.1" iyz="0.0" izz="0.1"/>
		</inertial>
	</link>
	<joint name="6_arm_r__7_arm_v" type="revolute">
		<limit effort="1000.0" lower="-0.5" upper="0.5" velocity="0"/>
		<axis xyz="0 1 0"/>
		<origin rpy="0 0 0" xyz="0.5 0 0"/>
		<parent link="6_arm_real"/>
		<child link="7_arm_virtual"/>
	</joint>
	<link name="7_arm_real">
		<visual>
			<geometry>
				<cylinder length="0.5" radius="0.25"/>
			</geometry>
			<origin rpy="0 1.571 0" xyz="0 0 0"/>
		</visual>
		<collision>
			<geometry>
				<cylinder length="0.5" radius="0.25"/>
			</geometry>
		</collision>
		<inertial>
			<mass value="1"/>
			<inertia ixx="0.1" ixy="0.0" ixz="0.0" iyy="0.1" iyz="0.0" izz="0.1"/>
		</inertial>
	</link>
	<joint name="7_arm_v__7_arm_r" type="revolute">
		<limit effort="1000.0" lower="-0.5" upper="0.5" velocity="0"/>
		<axis xyz="0 0 1"/>
		<origin rpy="0 0 0" xyz="0 0 0"/>
		<parent link="7_arm_virtual"/>
		<child link="7_arm_real"/>
	</joint>
	<link name="8_arm_virtual">
		<origin xyz="0 0 0"/>
		<inertial>
			<mass value="1"/>
			<inertia ixx="0.1" ixy="0.0" ixz="0.0" iyy="0.1" iyz="0.0" izz="0.1"/>
		</inertial>
	</link>
	<joint name="7_arm_r__8_arm_v" type="revolute">
		<limit effort="1000.0" lower="-0.5" upper="0.5" velocity="0"/>
		<axis xyz="0 1 0"/>
		<origin rpy="0 0 0" xyz="0.5 0 0"/>
		<parent link="7_arm_real"/>
		<child link="8_arm_virtual"/>
	</joint>
	<link name="8_arm_real">
		<visual>
			<geometry>
				<cylinder length="0.5" radius="0.25"/>
			</geometry>
			<origin rpy="0 1.571 0" xyz="0 0 0"/>
		</visual>
		<collision>
			<geometry>
				<cylinder length="0.5" radius="0.25"/>
			</geometry>
		</collision>
		<inertial>
			<mass value="1"/>
			<inertia ixx="0.1" ixy="0.0" ixz="0.0" iyy="0.1" iyz="0.0" izz="0.1"/>
		</inertial>
	</link>
	<joint name="8_arm_v__8_arm_r" type="revolute">
		<limit effort="1000.0" lower="-0.5" upper="0.5" velocity="0"/>
		<axis xyz="0 0 1"/>
		<origin rpy="0 0 0" xyz="0 0 0"/>
		<parent link="8_arm_virtual"/>
		<child link="8_arm_real"/>
	</joint>
	<link name="9_arm_virtual">
		<origin xyz="0 0 0"/>
		<inertial>
			<mass value="1"/>
			<inertia ixx="0.1" ixy="0.0" ixz="0.0" iyy="0.1" iyz="0.0" izz="0.1"/>
		</inertial>
	</link>
	<joint name="8_arm_r__9_arm_v" type="revolute">
		<limit effort="1000.0" lower="-0.5" upper="0.5" velocity="0"/>
		<axis xyz="0 1 0"/>
		<origin rpy="0 0 0" xyz="0.5 0 0"/>
		<parent link="8_arm_real"/>
		<child link="9_arm_virtual"/>
	</joint>
	<link name="9_arm_real">
		<visual>
			<geometry>
				<cylinder length="0.5" radius="0.25"/>
			</geometry>
			<origin rpy="0 1.571 0" xyz="0 0 0"/>
		</visual>
		<collision>
			<geometry>
				<cylinder length="0.5" radius="0.25"/>
			</geometry>
		</collision>
		<inertial>
			<mass value="1"/>
			<inertia ixx="0.1" ixy="0.0" ixz="0.0" iyy="0.1" iyz="0.0" izz="0.1"/>
		</inertial>
	</link>
	<joint name="9_arm_v__9_arm_r" type="revolute">
		<limit effort="1000.0" lower="-0.5" upper="0.5" velocity="0"/>
		<axis xyz="0 0 1"/>
		<origin rpy="0 0 0" xyz="0 0 0"/>
		<parent link="9_arm_virtual"/>
		<child link="9_arm_real"/>
	</joint>
	<link name="10_arm_virtual">
		<origin xyz="0 0 0"/>
		<inertial>
			<mass value="1"/>
			<inertia ixx="0.1" ixy="0.0" ixz="0.0" iyy="0.1" iyz="0.0" izz="0.1"/>
		</inertial>
	</link>
	<joint name="9_arm_r__10_arm_v" type="revolute">
		<limit effort="1000.0" lower="-0.5" upper="0.5" velocity="0"/>
		<axis xyz="0 1 0"/>
		<origin rpy="0 0 0" xyz="0.5 0 0"/>
		<parent link="9_arm_real"/>
		<child link="10_arm_virtual"/>
	</joint>
	<link name="10_arm_real">
		<visual>
			<geometry>
				<cylinder length="0.5" radius="0.25"/>
			</geometry>
			<origin rpy="0 1.571 0" xyz="0 0 0"/>
		</visual>
		<collision>
			<geometry>
				<cylinder length="0.5" radius="0.25"/>
			</geometry>
		</collision>
		<inertial>
			<mass value="1"/>
			<inertia ixx="0.1" ixy="0.0" ixz="0.0" iyy="0.1" iyz="0.0" izz="0.1"/>
		</inertial>
	</link>
	<joint name="10_arm_v__10_arm_r" type="revolute">
		<limit effort="1000.0" lower="-0.5" upper="0.5" velocity="0"/>
		<axis xyz="0 0 1"/>
		<origin rpy="0 0 0" xyz="0 0 0"/>
		<parent link="10_arm_virtual"/>
		<child link="10_arm_real"/>
	</joint>
	<link name="11_arm_virtual">
		<origin xyz="0 0 0"/>
		<inertial>
			<mass value="1"/>
			<inertia ixx="0.1" ixy="0.0" ixz="0.0" iyy="0.1" iyz="0.0" izz="0.1"/>
		</inertial>
	</link>
	<joint name="10_arm_r__11_arm_v" type="revolute">
		<limit effort="1000.0" lower="-0.5" upper="0.5" velocity="0"/>
		<axis xyz="0 1 0"/>
		<origin rpy="0 0 0" xyz="0.5 0 0"/>
		<parent link="10_arm_real"/>
		<child link="11_arm_virtual"/>
	</joint>
	<link name="11_arm_real">
		<visual>
			<geometry>
				<cylinder length="0.5" radius="0.25"/>
			</geometry>
			<origin rpy="0 1.571 0" xyz="0 0 0"/>
		</visual>
		<collision>
			<geometry>
				<cylinder length="0.5" radius="0.25"/>
			</geometry>
		</collision>
		<inertial>
			<mass value="1"/>
			<inertia ixx="0.1" ixy="0.0" ixz="0.0" iyy="0.1" iyz="0.0" izz="0.1"/>
		</inertial>
	</link>
	<joint name="11_arm_v__11_arm_r" type="revolute">
		<limit effort="1000.0" lower="-0.5" upper="0.5" velocity="0"/>
		<axis xyz="0 0 1"/>
		<origin rpy="0 0 0" xyz="0 0 0"/>
		<parent link="11_arm_virtual"/>
		<child link="11_arm_real"/>
	</joint>
	<link name="12_arm_virtual">
		<origin xyz="0 0 0"/>
		<inertial>
			<mass value="1"/>
			<inertia ixx="0.1" ixy="0.0" ixz="0.0" iyy="0.1" iyz="0.0" izz="0.1"/>
		</inertial>
	</link>
	<joint name="11_arm_r__12_arm_v" type="revolute">
		<limit effort="1000.0" lower="-0.5" upper="0.5" velocity="0"/>
		<axis xyz="0 1 0"/>
		<origin rpy="0 0 0" xyz="0.5 0 0"/>
		<parent link="11_arm_real"/>
		<child link="12_arm_virtual"/>
	</joint>
	<link name="12_arm_real">
		<visual>
			<geometry>
				<cylinder length="0.5" radius="0.25"/>
			</geometry>
			<origin rpy="0 1.571 0" xyz="0 0 0"/>
		</visual>
		<collision>
			<geometry>
				<cylinder length="0.5" radius="0.25"/>
			</geometry>
		</collision>
		<inertial>
			<mass value="1"/>
			<inertia ixx="0.1" ixy="0.0" ixz="0.0" iyy="0.1" iyz="0.0" izz="0.1"/>
		</inertial>
	</link>
	<joint name="12_arm_v__12_arm_r" type="revolute">
		<limit effort="1000.0" lower="-0.5" upper="0.5" velocity="0"/>
		<axis xyz="0 0 1"/>
		<origin rpy="0 0 0" xyz="0 0 0"/>
		<parent link="12_arm_virtual"/>
		<child link="12_arm_real"/>
	</joint>
</robot>
